Workbook

Sheet Word_tables
C5: S=25 | G5: EVP | K5: Stochastic - 2 stage | Q5: S=25
D6: alfa (%) | E6: VSS% | F6: Time (EVP) | G6: Gap (%) | H6: O_fs (%) | I6: F_fs (%) | J6: F_ss (%) | K6: Gap (%) | L6: O_fs (%) | M6: F_fs (%) | N6: F_ss (%) | R6: a (%) | S6: VSS% | T6: Time (s) | W6: VSS% | X6: Time (EVP) | Y6: EVP | AC6: Stochastic - 2 stage
C7: sp1 | D7: 5 | E7: 15.254193 | F7: 3683.1 | G7: 9.4008099 | H7: 90.434 | I7: 61.914 | J7: 25.579 | K7: 34.681205 | L7: 71.361 | M7: 63.502 | N7: 56.038 | Q7: sp1 | R7: 5 | S7: 15.254193 | T7: 3683.1 | Y7: Gap (%) | Z7: O_fs (%) | AA7: F_fs (%) | AB7: F_ss (%) | AC7: Gap (%) | AD7: O_fs (%) | AE7: F_fs (%) | AF7: F_ss (%)
D8: 10 | E8: 15.630463 | F8: 1958.5 | G8: 4.0667252 | H8: 92.464 | I8: 63.092 | J8: 25.68 | K8: 49.842471 | L8: 58.003 | M8: 52.9725 | N8: 54.279 | R8: 10 | S8: 15.630463 | T8: 1958.5 | W8: No Compatibility Constraints
D9: 20 | E9: 0.16622754 | F9: 3000.426 | G9: 8.8326575 | H9: 89.703 | I9: 62.396 | J9: 27.905 | K9: 40.67373 | L9: 74.536 | M9: 59.699 | N9: 49.809 | R9: 20 | S9: 0.16622754 | T9: 3000.426 | W9: 43.789068 | X9: 0.0866614 | Y9: 0.20219891 | Z9: 99.8 | AA9: 72.548 | AB9: 1.05 | AC9: 5.1206571 | AD9: 81.556 | AE9: 90.464 | AF9: 53.456
D10: 40 | E10: 2.4981648 | F10: 3324 | G10: 10.705893 | H10: 88.495 | I10: 62.065 | J10: 27.024 | K10: 40.103689 | L10: 89.11 | M10: 56.037 | N10: 26.884 | R10: 40 | S10: 2.4981648 | T10: 3324 | W10: No Same Type Constraints
C11: sp2 | D11: 5 | E11: 1.322303 | F11: 2043.4 | G11: 19.463888 | H11: 93.009 | I11: 67.713 | J11: 28.568 | K11: 42.772552 | L11: 72.124 | M11: 61.183333 | N11: 50.939 | Q11: sp2 | R11: 5 | S11: 1.322303 | T11: 2043.4 | W11: 32.811974 | X11: 0.127162 | Y11: 0 | Z11: 100 | AA11: 71.358 | AB11: - | AC11: 12.889337 | AD11: 80.92 | AE11: 85.282 | AF11: 50.866
D12: 10 | E12: 5.2861447 | F12: 1541 | G12: 2.0424144 | H12: 92.288 | I12: 69.372 | J12: 29.946 | K12: 35.042056 | L12: 76.677 | M12: 65.115 | N12: 49.045 | R12: 10 | S12: 5.2861447 | T12: 1541 | W12: All Compatibility Constraints
D13: 20 | E13: 0.033198694 | F13: 1840.9 | G13: 3.937349 | H13: 91.272 | I13: 68.421 | J13: 32.177 | K13: 41.479924 | L13: 89.876 | M13: 58.529 | N13: 29.456 | R13: 20 | S13: 0.033198694 | T13: 1840.9 | W13: 2.4981648 | X13: 3324 | Y13: 10.705893 | Z13: 88.495 | AA13: 62.065 | AB13: 27.024 | AC13: 40.103689 | AD13: 89.11 | AE13: 56.037 | AF13: 26.884
D14: 40 | E14: 10.276811 | F14: 3317 | G14: 11.377668 | H14: 87.565 | I14: 67.073 | J14: 27.975 | K14: 37.932577 | L14: 89.55 | M14: 59.355 | N14: 26.858 | R14: 40 | S14: 10.276811 | T14: 3317
C15: sp3 | D15: 5 | E15: 2.3683894 | F15: 1351.5 | G15: 2.5991653 | H15: 91.561 | I15: 65.927 | J15: 29.62 | K15: 26.420913 | L15: 76.172 | M15: 66.545 | N15: 52.326 | Q15: sp3 | R15: 5 | S15: 2.3683894 | T15: 1351.5
D16: 10 | E16: 10.093235 | F16: 1562.1 | G16: 3.4134117 | H16: 91.734 | I16: 65.388 | J16: 28.614 | K16: 36.91858 | L16: 80.744 | M16: 63.203 | N16: 46.972 | R16: 10 | S16: 10.093235 | T16: 1562.1
D17: 20 | E17: 2.4305922 | F17: 3858.4 | G17: 12.706156 | H17: 86.15 | I17: 65.28 | J17: 31.107 | K17: 38.888721 | L17: 85.201 | M17: 59.547 | N17: 35.138 | R17: 20 | S17: 2.4305922 | T17: 3858.4
D18: 40 | E18: 8.3136805 | F18: 1505.813 | G18: 1.5532335 | H18: 89.146 | I18: 64.836 | J18: 30.014 | K18: 31.904799 | L18: 87.753 | M18: 60.375 | N18: 29.625 | R18: 40 | S18: 8.3136805 | T18: 1505.813
C22: S = 25 | K22: S = 25 | V22: Constraints Modification | W22: VSS% | X22: Time (s) | Y22: EVP | AC22: Stochastic - 2 stage
C23: EVP | K23: 2 - Stage Stochastic | M23: Stochastic - 2 stage | Y23: Gap (%) | Z23: O_fs (%) | AA23: F_fs (%) | AB23: F_ss (%) | AC23: Gap (%) | AD23: O_fs (%) | AE23: F_fs (%) | AF23: F_ss (%)
D24: a (%) | E24: Gap (%) | F24: O_fs (%) | G24: F_fs (%) | H24: F_ss (%) | L24: a (%) | M24: Gap (%) | N24: O_fs (%) | O24: F_fs (%) | P24: F_ss (%) | V24: No Compatibility Constraints | W24: 43.789068 | X24: 0.0866614 | Y24: 0.20219891 | Z24: 99.8 | AA24: 72.548 | AB24: 1.05 | AC24: 5.1206571 | AD24: 81.556 | AE24: 90.464 | AF24: 53.456
C25: sp1 | D25: 5 | E25: 9.4008099 | F25: 90.434 | G25: 61.914 | H25: 25.579 | K25: sp1 | L25: 5 | M25: 34.681205 | N25: 71.361 | O25: 63.502 | P25: 56.038 | V25: No Same Type Constraints | W25: 32.811974 | X25: 0.127162 | Y25: 0 | Z25: 100 | AA25: 71.358 | AB25: - | AC25: 12.889337 | AD25: 80.92 | AE25: 85.282 | AF25: 50.866
D26: 10 | E26: 4.0667252 | F26: 92.464 | G26: 63.092 | H26: 25.68 | L26: 10 | M26: 49.842471 | N26: 58.003 | O26: 52.9725 | P26: 54.279 | V26: All Compatibility Constraints | W26: 2.4981648 | X26: 3324 | Y26: 10.705893 | Z26: 88.495 | AA26: 62.065 | AB26: 27.024 | AC26: 40.103689 | AD26: 89.11 | AE26: 56.037 | AF26: 26.884
D27: 20 | E27: 8.8326575 | F27: 89.703 | G27: 62.396 | H27: 27.905 | L27: 20 | M27: 40.67373 | N27: 74.536 | O27: 59.699 | P27: 49.809
D28: 40 | E28: 10.705893 | F28: 88.495 | G28: 62.065 | H28: 27.024 | L28: 40 | M28: 40.103689 | N28: 89.11 | O28: 56.037 | P28: 26.884
C29: sp2 | D29: 5 | E29: 19.463888 | F29: 93.009 | G29: 67.713 | H29: 28.568 | K29: sp2 | L29: 5 | M29: 42.772552 | N29: 72.124 | O29: 61.183333 | P29: 50.939
D30: 10 | E30: 2.0424144 | F30: 92.288 | G30: 69.372 | H30: 29.946 | L30: 10 | M30: 35.042056 | N30: 76.677 | O30: 65.115 | P30: 49.045 | U30: S | V30: VSS% | W30: Time (s) | X30: EVP | AB30: 2-Stage Stochastic
D31: 20 | E31: 3.937349 | F31: 91.272 | G31: 68.421 | H31: 32.177 | L31: 20 | M31: 41.479924 | N31: 89.876 | O31: 58.529 | P31: 29.456 | X31: Gap(%) | Y31: O_fs (%) | Z31: F_fs (%) | AA31: F_ss (%) | AB31: Gap (%) | AC31: O_fs (%) | AD31: F_fs (%) | AE31: F_ss (%)
D32: 40 | E32: 11.377668 | F32: 87.565 | G32: 67.073 | H32: 27.975 | L32: 40 | M32: 37.932577 | N32: 89.55 | O32: 59.355 | P32: 26.858 | U32: S = 3 | V32: 22.722494 | W32: 374.94021 | X32: 0.81991287 | Y32: 96.896 | Z32: 59.86 | AA32: 24.58 | AB32: 44.576938 | AC32: 70.432 | AD32: 64.616 | AE32: 60.652
C33: sp3 | D33: 5 | E33: 2.5991653 | F33: 91.561 | G33: 65.927 | H33: 29.62 | K33: sp3 | L33: 5 | M33: 26.420913 | N33: 76.172 | O33: 66.545 | P33: 52.326 | U33: S = 10 | V33: 15.166885 | W33: 1786.132 | X33: 2.689776 | Y33: 93.53 | Z33: 60.842 | AA33: 22.482 | AB33: 34.568608 | AC33: 71.246 | AD33: 62.954 | AE33: 55.328
D34: 10 | E34: 3.4134117 | F34: 91.734 | G34: 65.388 | H34: 28.614 | L34: 10 | M34: 36.91858 | N34: 80.744 | O34: 63.203 | P34: 46.972 | U34: S = 25 | V34: 15.254193 | W34: 3683.1 | X34: 9.4008099 | Y34: 90.434 | Z34: 61.914 | AA34: 25.579 | AB34: 34.681205 | AC34: 71.361 | AD34: 63.502 | AE34: 56.038
D35: 20 | E35: 12.706156 | F35: 86.15 | G35: 65.28 | H35: 31.107 | L35: 20 | M35: 38.888721 | N35: 85.201 | O35: 59.547 | P35: 35.138
D36: 40 | E36: 1.5532335 | F36: 89.146 | G36: 64.836 | H36: 30.014 | L36: 40 | M36: 31.904799 | N36: 87.753 | O36: 60.375 | P36: 29.625

Sheet Summary
Q6: Fewer Scenarios
B7: S=25 | G7: EVP | K7: Stochastic - 2 stage | Q7: S=3 | V7: EVP | Z7: Stochastic - 2 stage
C8: alfa (%) | D8: VSS% | E8: Time (EVP) | F8: Time (Stochastic) | G8: Gap (%) | H8: O_fs (%) | I8: F_fs (%) | J8: F_ss (%) | K8: Gap (%) | L8: O_fs (%) | M8: F_fs (%) | N8: F_ss (%) | R8: alfa (%) | S8: VSS% | T8: Time (EVP) | U8: Time (Stochastic) | V8: Gap (%) | W8: O_fs (%) | X8: F_fs (%) | Y8: F_ss (%) | Z8: Gap (%) | AA8: O_fs (%) | AB8: F_fs (%) | AC8: F_ss (%)
B9: sp1 | C9: 5 | D9: =sp1_25_a5!$O$7 -> 15.254193 | E9: =sp1_25_a5!$D$25 -> 3683.1 | F9: =sp1_25_a5!$E$41 -> 1975.7 | G9: =sp1_25_a5!$E$26 -> 9.4008099 | H9: =sp1_25_a5!$H$25 -> 90.434 | I9: =sp1_25_a5!$I$25 -> 61.914 | J9: =sp1_25_a5!$J$25 -> 25.579 | K9: =sp1_25_a5!$F$42 -> 34.681205 | L9: =sp1_25_a5!$I$41 -> 71.361 | M9: =sp1_25_a5!$J$41 -> 63.502 | N9: =sp1_25_a5!$K$41 -> 56.038 | Q9: sp1 | R9: 40 | S9: ='3_scenario_a5'!$O$7 -> 22.722494 | T9: ='3_scenario_a5'!$D$25 -> 374.94021 | U9: ='3_scenario_a5'!$E$41 -> 2085 | V9: ='3_scenario_a5'!$E$26 -> 0.81991287 | W9: ='3_scenario_a5'!$H$25 -> 96.896 | X9: ='3_scenario_a5'!$I$25 -> 59.86 | Y9: ='3_scenario_a5'!$J$25 -> 24.58 | Z9: ='3_scenario_a5'!$F$42 -> 44.576938 | AA9: ='3_scenario_a5'!$I$41 -> 70.432 | AB9: ='3_scenario_a5'!$J$41 -> 64.616 | AC9: ='3_scenario_a5'!$K$41 -> 60.652
C10: 10 | D10: =sp1_25_a10!O7 -> 15.630463 | E10: =sp1_25_a10!D25 -> 1958.5 | F10: =sp1_25_a10!E41 -> 3797.8 | G10: =sp1_25_a10!E26 -> 4.0667252 | H10: =sp1_25_a10!H25 -> 92.464 | I10: =sp1_25_a10!I25 -> 63.092 | J10: =sp1_25_a10!J25 -> 25.68 | K10: =sp1_25_a10!F42 -> 49.842471 | L10: =sp1_25_a10!I41 -> 58.003 | M10: =sp1_25_a10!J41 -> 52.9725 | N10: =sp1_25_a10!K41 -> 54.279 | Q10: S = 10
C11: 20 | D11: =sp1_25_a20!O7 -> 0.16622754 | E11: =sp1_25_a20!D25 -> 3000.426 | F11: =sp1_25_a20!E41 -> 2265.5 | G11: =sp1_25_a20!E26 -> 8.8326575 | H11: =sp1_25_a20!H25 -> 89.703 | I11: =sp1_25_a20!I25 -> 62.396 | J11: =sp1_25_a20!J25 -> 27.905 | K11: =sp1_25_a20!F42 -> 40.67373 | L11: =sp1_25_a20!I41 -> 74.536 | M11: =sp1_25_a20!J41 -> 59.699 | N11: =sp1_25_a20!K41 -> 49.809 | Q11: sp1 | R11: 40 | S11: ='10_scenario_a5'!$O$7 -> 15.166885 | T11: ='10_scenario_a5'!$D$25 -> 1786.132 | U11: ='10_scenario_a5'!$E$41 -> 2103.8 | V11: ='10_scenario_a5'!$E$26 -> 2.689776 | W11: ='10_scenario_a5'!$H$25 -> 93.53 | X11: ='10_scenario_a5'!$I$25 -> 60.842 | Y11: ='10_scenario_a5'!$J$25 -> 22.482 | Z11: ='10_scenario_a5'!$F$42 -> 34.568608 | AA11: ='10_scenario_a5'!$I$41 -> 71.246 | AB11: ='10_scenario_a5'!$J$41 -> 62.954 | AC11: ='10_scenario_a5'!$K$41 -> 55.328
C12: 40 | D12: =sp1_25_a40!O7 -> 2.4981648 | E12: =sp1_25_a40!D25 -> 3324 | F12: =sp1_25_a40!E41 -> 1958.2 | G12: =sp1_25_a40!E26 -> 10.705893 | H12: =sp1_25_a40!H25 -> 88.495 | I12: =sp1_25_a40!I25 -> 62.065 | J12: =sp1_25_a40!J25 -> 27.024 | K12: =sp1_25_a40!F42 -> 40.103689 | L12: =sp1_25_a40!I41 -> 89.11 | M12: =sp1_25_a40!J41 -> 56.037 | N12: =sp1_25_a40!K41 -> 26.884
B13: sp2 | C13: 5 | D13: =sp2_25_a5!O7 -> 1.322303 | E13: =sp2_25_a5!D25 -> 2043.4 | F13: =sp2_25_a5!E41 -> 3778 | G13: =sp2_25_a5!E26 -> 19.463888 | H13: =sp2_25_a5!H25 -> 93.009 | I13: =sp2_25_a5!I25 -> 67.713 | J13: =sp2_25_a5!J25 -> 28.568 | K13: =sp2_25_a5!F42 -> 42.772552 | L13: =sp2_25_a5!I41 -> 72.124 | M13: =sp2_25_a5!J41 -> 61.183333 | N13: =sp2_25_a5!K41 -> 50.939 | Q13: No conraints on items' types
C14: 10 | D14: =sp2_25_a10!O7 -> 5.2861447 | E14: =sp2_25_a10!D25 -> 1541 | F14: =sp2_25_a10!E41 -> 1855.1 | G14: =sp2_25_a10!E26 -> 2.0424144 | H14: =sp2_25_a10!H25 -> 92.288 | I14: =sp2_25_a10!I25 -> 69.372 | J14: =sp2_25_a10!J25 -> 29.946 | K14: =sp2_25_a10!F42 -> 35.042056 | L14: =sp2_25_a10!I41 -> 76.677 | M14: =sp2_25_a10!J41 -> 65.115 | N14: =sp2_25_a10!K41 -> 49.045 | Q14: S=25 | V14: EVP | Z14: Stochastic - 2 stage
C15: 20 | D15: =sp2_25_a20!O7 -> 0.033198694 | E15: =sp2_25_a20!D25 -> 1840.9 | F15: =sp2_25_a20!E41 -> 3874.6 | G15: =sp2_25_a20!E26 -> 3.937349 | H15: =sp2_25_a20!H25 -> 91.272 | I15: =sp2_25_a20!I25 -> 68.421 | J15: =sp2_25_a20!J25 -> 32.177 | K15: =sp2_25_a20!F42 -> 41.479924 | L15: =sp2_25_a20!I41 -> 89.876 | M15: =sp2_25_a20!J41 -> 58.529 | N15: =sp2_25_a20!K41 -> 29.456 | R15: alfa (%) | S15: VSS% | T15: Time (EVP) | U15: Time (Stochastic) | V15: Gap (%) | W15: O_fs (%) | X15: F_fs (%) | Y15: F_ss (%) | Z15: Gap (%) | AA15: O_fs (%) | AB15: F_fs (%) | AC15: F_ss (%)
C16: 40 | D16: =sp2_25_a40!O7 -> 10.276811 | E16: =sp2_25_a40!D25 -> 3317 | F16: =sp2_25_a40!E41 -> 2990.7 | G16: =sp2_25_a40!E26 -> 11.377668 | H16: =sp2_25_a40!H25 -> 87.565 | I16: =sp2_25_a40!I25 -> 67.073 | J16: =sp2_25_a40!J25 -> 27.975 | K16: =sp2_25_a40!F42 -> 37.932577 | L16: =sp2_25_a40!I41 -> 89.55 | M16: =sp2_25_a40!J41 -> 59.355 | N16: =sp2_25_a40!K41 -> 26.858 | Q16: sp1 | R16: 40 | S16: =no_type!$O$7 -> 43.789068 | T16: =no_type!$D$25 -> 0.0866614 | U16: =no_type!$E$41 -> 2045.2 | V16: =no_type!$E$26 -> 0.20219891 | W16: =no_type!$H$25 -> 99.8 | X16: =no_type!$I$25 -> 72.548 | Y16: =no_type!$J$25 -> 1.05 | Z16: =no_type!$F$42 -> 5.1206571 | AA16: =no_type!$I$41 -> 81.556 | AB16: =no_type!$J$41 -> 90.464 | AC16: =no_type!$K$41 -> 53.456
B17: sp3 | C17: 5 | D17: =sp3_25_a5!O7 -> 2.3683894 | E17: =sp3_25_a5!D25 -> 1351.5 | F17: =sp3_25_a5!E41 -> 1815.9 | G17: =sp3_25_a5!E26 -> 2.5991653 | H17: =sp3_25_a5!H25 -> 91.561 | I17: =sp3_25_a5!I25 -> 65.927 | J17: =sp3_25_a5!J25 -> 29.62 | K17: =sp3_25_a5!F42 -> 26.420913 | L17: =sp3_25_a5!I41 -> 76.172 | M17: =sp3_25_a5!J41 -> 66.545 | N17: =sp3_25_a5!K41 -> 52.326 | Q17: No same type constraints
C18: 10 | D18: =sp3_25_a10!O7 -> 10.093235 | E18: =sp3_25_a10!D25 -> 1562.1 | F18: =sp3_25_a10!E41 -> 3851.2 | G18: =sp3_25_a10!E26 -> 3.4134117 | H18: =sp3_25_a10!H25 -> 91.734 | I18: =sp3_25_a10!I25 -> 65.388 | J18: =sp3_25_a10!J25 -> 28.614 | K18: =sp3_25_a10!F42 -> 36.91858 | L18: =sp3_25_a10!I41 -> 80.744 | M18: =sp3_25_a10!J41 -> 63.203 | N18: =sp3_25_a10!K41 -> 46.972 | Q18: sp1 | R18: 40 | S18: =no_same_type!$O$7 -> 32.811974 | T18: =no_same_type!$D$25 -> 0.127162 | U18: =no_same_type!$E$41 -> 3615.8 | V18: =no_same_type!$E$26 -> 0 | W18: =no_same_type!$H$25 -> 100 | X18: =no_same_type!$I$25 -> 71.358 | Y18: =IFERROR(no_same_type!$J$25,"-") -> - | Z18: =no_same_type!$F$42 -> 12.889337 | AA18: =no_same_type!$I$41 -> 80.92 | AB18: =no_same_type!$J$41 -> 85.282 | AC18: =no_same_type!$K$41 -> 50.866
C19: 20 | D19: =sp3_25_a20!O7 -> 2.4305922 | E19: =sp3_25_a20!D25 -> 3858.4 | F19: =sp3_25_a20!E41 -> 3959.8 | G19: =sp3_25_a20!E26 -> 12.706156 | H19: =sp3_25_a20!H25 -> 86.15 | I19: =sp3_25_a20!I25 -> 65.28 | J19: =sp3_25_a20!J25 -> 31.107 | K19: =sp3_25_a20!F42 -> 38.888721 | L19: =sp3_25_a20!I41 -> 85.201 | M19: =sp3_25_a20!J41 -> 59.547 | N19: =sp3_25_a20!K41 -> 35.138
C20: 40 | D20: =sp3_25_a40!O7 -> 8.3136805 | E20: =sp3_25_a40!D25 -> 1505.813 | F20: =sp3_25_a40!E41 -> 1945.1 | G20: =sp3_25_a40!E26 -> 1.5532335 | H20: =sp3_25_a40!H25 -> 89.146 | I20: =sp3_25_a40!I25 -> 64.836 | J20: =sp3_25_a40!J25 -> 30.014 | K20: =sp3_25_a40!F42 -> 31.904799 | L20: =sp3_25_a40!I41 -> 87.753 | M20: =sp3_25_a40!J41 -> 60.375 | N20: =sp3_25_a40!K41 -> 29.625
B24: sp1 | H24: sp2 | N24: sp3
B26: Alpha | C26: Method | D26: 2SS | E26: Heuristic | F26: Gap cost | H26: Alpha | I26: Method | J26: 2SS | K26: Heuristic | L26: Gap cost | N26: Alpha | O26: Method | P26: 2SS | Q26: Heuristic | R26: Gap cost | U26: Alpha | V26: Gap cost
B27: 5 | C27: Total cost | D27: =sp1_25_a5!D41 -> 75.848 | E27: ='Hss-sp1_25'!C26 -> 92.403611 | F27: =((E27-D27)/D27) -> 0.21827354 | H27: 5 | I27: Total cost | J27: =sp2_25_a5!D41 -> 105.044 | K27: ='Hss-sp2_25'!$C26 -> 119.35778 | L27: =((K27-J27)/J27) -> 0.13626459 | N27: 5 | O27: Total cost | P27: =sp3_25_a5!D41 -> 124.515 | Q27: ='Hss-sp3_25'!C26 -> 152.47667 | R27: =((Q27-P27)/P27) -> 0.22456464 | U27: 5 | V27: =AVERAGE(F27,L27,R27) -> 0.19303426
C28: F_fs (%) | D28: =M9 -> 63.502 | E28: ='Hss-sp1_25'!F26*100 -> 62.917778 | F28: - | I28: F_fs (%) | J28: =M13 -> 61.183333 | K28: ='Hss-sp2_25'!$F26*100 -> 67.546667 | L28: - | O28: F_fs (%) | P28: =M17 -> 66.545 | Q28: ='Hss-sp3_25'!F26*100 -> 66.37 | R28: - | U28: 10 | V28: =AVERAGE(F30,L30,R30) -> 0.1941318
C29: F_ss (%) | D29: =N9 -> 56.038 | E29: ='Hss-sp1_25'!G26*100 -> 59.244444 | F29: - | I29: F_ss (%) | J29: =N13 -> 50.939 | K29: ='Hss-sp2_25'!$G26*100 -> 59.496667 | L29: - | O29: F_ss (%) | P29: =N17 -> 52.326 | Q29: ='Hss-sp3_25'!G26*100 -> 56.37125 | R29: - | U29: 20 | V29: =AVERAGE(F33,L33,R33) -> 0.2723905
B30: 10 | C30: Total cost | D30: =sp1_25_a10!D41 -> 101.251 | E30: ='Hss-sp1_25'!C43 -> 108.97622 | F30: =((E30-D30)/D30) -> 0.076297738 | H30: 10 | I30: Total cost | J30: =sp2_25_a10!D41 -> 101.889 | K30: ='Hss-sp2_25'!$C43 -> 127.42222 | L30: =((K30-J30)/J30) -> 0.25059842 | N30: 10 | O30: Total cost | P30: =sp3_25_a10!D41 -> 115.622 | Q30: ='Hss-sp3_25'!C43 -> 145.16333 | R30: =((Q30-P30)/P30) -> 0.25549924 | U30: 40 | V30: =AVERAGE(F36,L36,R36) -> 0.38439614
C31: F_fs (%) | D31: =M10 -> 52.9725 | E31: ='Hss-sp1_25'!F43*100 -> 59.933333 | F31: - | I31: F_fs (%) | J31: =M14 -> 65.115 | K31: ='Hss-sp2_25'!$F43*100 -> 68.64 | L31: - | O31: F_fs (%) | P31: =M18 -> 63.203 | Q31: ='Hss-sp3_25'!F43*100 -> 68.332222 | R31: -
C32: F_ss (%) | D32: =N10 -> 54.279 | E32: ='Hss-sp1_25'!G43*100 -> 61.847778 | F32: - | I32: F_ss (%) | J32: =N14 -> 49.045 | K32: ='Hss-sp2_25'!$G43*100 -> 53.9875 | L32: - | O32: F_ss (%) | P32: =N18 -> 46.972 | Q32: ='Hss-sp3_25'!G43*100 -> 50.243333 | R32: -
B33: 20 | C33: Total cost | D33: =sp1_25_a20!D41 -> 88.433 | E33: ='Hss-sp1_25'!C60 -> 106.71111 | F33: =((E33-D33)/D33) -> 0.20668881 | H33: 20 | I33: Total cost | J33: =sp2_25_a20!D41 -> 108.438 | K33: ='Hss-sp2_25'!$C60 -> 141.64889 | L33: =((K33-J33)/J33) -> 0.30626615 | N33: 20 | O33: Total cost | P33: =sp3_25_a20!D41 -> 132.478 | Q33: ='Hss-sp3_25'!C60 -> 172.78 | R33: =((Q33-P33)/P33) -> 0.30421655
C34: F_fs (%) | D34: =M11 -> 59.699 | E34: ='Hss-sp1_25'!F60*100 -> 63.555556 | F34: - | I34: F_fs (%) | J34: =M15 -> 58.529 | K34: ='Hss-sp2_25'!$F60*100 -> 69.311111 | L34: - | O34: F_fs (%) | P34: =M19 -> 59.547 | Q34: ='Hss-sp3_25'!F60*100 -> 68.441111 | R34: -
C35: F_ss (%) | D35: =N11 -> 49.809 | E35: ='Hss-sp1_25'!G60*100 -> 55.855 | F35: - | I35: F_ss (%) | J35: =N15 -> 29.456 | K35: ='Hss-sp2_25'!$G60*100 -> 61.577778 | L35: - | O35: F_ss (%) | P35: =N19 -> 35.138 | Q35: ='Hss-sp3_25'!G60*100 -> 55.53875 | R35: -
B36: 40 | C36: Total cost | D36: ='3_scenario_a5'!D41 -> 66.586 | E36: ='Hss-sp1_25'!C77 -> 116.37778 | F36: =((E36-D36)/D36) -> 0.74778148 | H36: 40 | I36: Total cost | J36: =sp2_25_a40!D41 -> 102.814 | K36: ='Hss-sp2_25'!$C77 -> 133.57778 | L36: =((K36-J36)/J36) -> 0.29921779 | N36: 40 | O36: Total cost | P36: =sp3_25_a40!D41 -> 142.897 | Q36: ='Hss-sp3_25'!C77 -> 158.07111 | R36: =((Q36-P36)/P36) -> 0.10618915
C37: F_fs (%) | D37: =M12 -> 56.037 | E37: ='Hss-sp1_25'!F77*100 -> 63.935556 | F37: - | I37: F_fs (%) | J37: =M16 -> 59.355 | K37: ='Hss-sp2_25'!$F77*100 -> 68.45 | L37: - | O37: F_fs (%) | P37: =M20 -> 60.375 | Q37: ='Hss-sp3_25'!F77*100 -> 65.951111 | R37: -
C38: F_ss (%) | D38: =N12 -> 26.884 | E38: ='Hss-sp1_25'!G77*100 -> 67.98 | F38: - | I38: F_ss (%) | J38: =N16 -> 26.858 | K38: ='Hss-sp2_25'!$G77*100 -> 66.1975 | L38: - | O38: F_ss (%) | P38: =N20 -> 29.625 | Q38: ='Hss-sp3_25'!G77*100 -> 52.682857 | R38: -

Sheet no_type
A1: bins J (1° stage) | B1: 7 | C1: 11 | D1: 13 | E1: 14 | F1: 15 | G1: 16 | H1: 17 | I1: 21 | N1: # fixed bins | O1: OF | P1: Time | Q1: Gap | R1: LB
A2: deterministic solution | N2: 8 | O2: 78.97 | P2: 900 | Q2: 0.2335 | R2: 60.53
A3: EVP
O6: VSS%
O7: =((ABS(C25-D41))/D41)*100 -> 43.789068
A13: zEVP | B13: # bins extra | C13: OF | D13: time_execution | E13: Gap | F13: LB | G13: Optimality reached? | H13: O_fs | I13: F_fs | J13: F_ss | K13: #items
A14: 1 | B14: 0.04 | C14: 79.37 | D14: 0.08097 | E14: 0.4989 | F14: 78.97 | G14: =IF(E14=0,"Yes","No") -> No | H14: 99.5 | I14: 68.69 | J14: 1.11
A15: 2 | B15: 0.04 | C15: 79.37 | D15: 0.08804 | E15: 0.4989 | F15: 78.97 | G15: =IF(E15=0,"Yes","No") -> No | H15: 99.5 | I15: 73.8 | J15: 0.99
A16: 3 | B16: 0 | C16: 78.97 | D16: 0.08367 | E16: 0 | F16: 78.97 | G16: =IF(E16=0,"Yes","No") -> Yes | H16: 100 | I16: 73.21
A17: 4 | B17: 0 | C17: 78.97 | D17: 0.07943 | E17: 0 | F17: 78.97 | G17: =IF(E17=0,"Yes","No") -> Yes | H17: 100 | I17: 72.67
A18: 5 | B18: 0 | C18: 78.97 | D18: 0.101197 | E18: 0 | F18: 78.97 | G18: =IF(E18=0,"Yes","No") -> Yes | H18: 100 | I18: 74.37
A19: 6 | G19: =IF(E19=0,"Yes","No") -> Yes
A20: 7 | G20: =IF(E20=0,"Yes","No") -> Yes
A21: 8 | G21: =IF(E21=0,"Yes","No") -> Yes
A22: 9 | G22: =IF(E22=0,"Yes","No") -> Yes
A23: 10 | G23: =IF(E23=0,"Yes","No") -> Yes
A25: avg | B25: =AVERAGE(B14:B23) -> 0.016 | C25: =AVERAGE(C14:C23) -> 79.13 | D25: =AVERAGE(D14:D23) -> 0.0866614 | E25: =AVERAGE(E14:E23) -> 0.19956 | F25: =AVERAGE(F14:F23) -> 78.97 | G25: =(COUNTIF(G14:G23,"Yes")/10)*100 -> 80 | H25: =AVERAGE(H14:H23) -> 99.8 | I25: =AVERAGE(I14:I23) -> 72.548 | J25: =AVERAGE(J14:J23) -> 1.05 | K25: =AVERAGE(K14:K23) -> #DIV/0!
E26: =((C25-F25)/C25)*100 -> 0.20219891
A29: Stochastic 2 stage | B29: # fixed bins | C29: bins extra | D29: OF | E29: time_execution | F29: Gap | G29: LB | H29: Optimality reached? | I29: O_fs | J29: F_fs | K29: F_ss | L29: # items
A30: 1 | B30: 5 | C30: 0.72 | D30: 44.98 | E30: 1976 | F30: 2.3698 | G30: 43.92 | H30: =IF(F30=0,"Yes","No") -> No | I30: 84.03 | J30: 90.11 | K30: 49.49
A31: 2 | B31: 5 | C31: 1.12 | D31: 51.98 | E31: 2850 | F31: 5.0381 | G31: 49.36 | H31: =IF(F31=0,"Yes","No") -> No | I31: 77.25 | J31: 91.98 | K31: 62.2
A32: 3 | B32: 6 | C32: 0.56 | D32: 65.46 | E32: 1800 | F32: 7.9375 | G32: 60.26 | H32: =IF(F32=0,"Yes","No") -> No | I32: 89.89 | J32: 87.46 | K32: 38.88
A33: 4 | B33: 5 | C33: 0.88 | D33: 61.68 | E33: 1800 | F33: 5.5369 | G33: 58.27 | H33: =IF(F33=0,"Yes","No") -> No | I33: 80.82 | J33: 90.15 | K33: 50.8
A34: 5 | B34: 5 | C34: 1.16 | D34: 51.06 | E34: 1800 | F34: 3.5232 | G34: 49.26 | H34: =IF(F34=0,"Yes","No") -> No | I34: 75.79 | J34: 92.62 | K34: 65.91
A35: 6 | H35: =IF(F35=0,"Yes","No") -> Yes
A36: 7 | H36: =IF(F36=0,"Yes","No") -> Yes
A37: 8 | H37: =IF(F37=0,"Yes","No") -> Yes
A38: 9 | H38: =IF(F38=0,"Yes","No") -> Yes
A39: 10 | H39: =IF(F39=0,"Yes","No") -> Yes
A41: avg | B41: =AVERAGE(B30:B39) -> 5.2 | C41: =AVERAGE(C30:C39) -> 0.888 | D41: =AVERAGE(D30:D39) -> 55.032 | E41: =AVERAGE(E30:E39) -> 2045.2 | F41: =AVERAGE(F30:F39) -> 4.8811 | G41: =AVERAGE(G30:G39) -> 52.214 | H41: =(COUNTIF(H30:H39,"Yes")/10)*100 -> 50 | I41: =AVERAGE(I30:I39) -> 81.556 | J41: =AVERAGE(J30:J39) -> 90.464 | K41: =AVERAGE(K30:K39) -> 53.456 | L41: =AVERAGE(L30:L39) -> #DIV/0!
F42: =((D41-G41)/D41)*100 -> 5.1206571

Sheet no_same_type
A1: bins J (1° stage) | B1: 7 | C1: 11 | D1: 13 | E1: 14 | F1: 15 | G1: 16 | H1: 17 | I1: 21 | N1: # fixed bins | O1: OF | P1: Time | Q1: Gap | R1: LB
A2: deterministic solution | N2: 8 | O2: 78.97 | P2: 900 | Q2: 0.2335 | R2: 60.53
A3: EVP
O6: VSS%
O7: =((ABS(C25-D41))/D41)*100 -> 32.811974
A13: zEVP | B13: # bins extra | C13: OF | D13: time_execution | E13: Gap | F13: LB | G13: Optimality reached? | H13: O_fs | I13: F_fs | J13: F_ss | K13: #items
A14: 1 | B14: 0 | C14: 78.97 | D14: 0.23205 | E14: 0 | F14: 78.97 | G14: =IF(E14=0,"Yes","No") -> Yes | H14: 100 | I14: 69.34
A15: 2 | B15: 0 | C15: 78.97 | D15: 0.10295 | E15: 0 | F15: 78.97 | G15: =IF(E15=0,"Yes","No") -> Yes | H15: 100 | I15: 71.7
A16: 3 | B16: 0 | C16: 78.97 | D16: 0.0988 | E16: 0 | F16: 78.97 | G16: =IF(E16=0,"Yes","No") -> Yes | H16: 100 | I16: 71.58
A17: 4 | B17: 0 | C17: 78.97 | D17: 0.09415 | E17: 0 | F17: 78.97 | G17: =IF(E17=0,"Yes","No") -> Yes | H17: 100 | I17: 69.54
A18: 5 | B18: 0 | C18: 78.97 | D18: 0.10786 | E18: 0 | F18: 78.97 | G18: =IF(E18=0,"Yes","No") -> Yes | H18: 100 | I18: 74.63
A19: 6 | G19: =IF(E19=0,"Yes","No") -> Yes
A20: 7 | G20: =IF(E20=0,"Yes","No") -> Yes
A21: 8 | G21: =IF(E21=0,"Yes","No") -> Yes
A22: 9 | G22: =IF(E22=0,"Yes","No") -> Yes
A23: 10 | G23: =IF(E23=0,"Yes","No") -> Yes
A25: avg | B25: =AVERAGE(B14:B23) -> 0 | C25: =AVERAGE(C14:C23) -> 78.97 | D25: =AVERAGE(D14:D23) -> 0.127162 | E25: =AVERAGE(E14:E23) -> 0 | F25: =AVERAGE(F14:F23) -> 78.97 | G25: =(COUNTIF(G14:G23,"Yes")/10)*100 -> 100 | H25: =AVERAGE(H14:H23) -> 100 | I25: =AVERAGE(I14:I23) -> 71.358 | J25: =AVERAGE(J14:J23) -> #DIV/0! | K25: =AVERAGE(K14:K23) -> #DIV/0!
E26: =((C25-F25)/C25)*100 -> 0
A29: Stochastic 2 stage | B29: # fixed bins | C29: bins extra | D29: OF | E29: time_execution | F29: Gap | G29: LB | H29: Optimality reached? | I29: O_fs | J29: F_fs | K29: F_ss | L29: # items
A30: 1 | B30: 5 | C30: 0.76 | D30: 45.06 | E30: 3949 | F30: 2.4739 | G30: 43.94 | H30: =IF(F30=0,"Yes","No") -> No | I30: 83.89 | J30: 90.08 | K30: 46.79
A31: 2 | B31: 5 | C31: 1.12 | D31: 52.28 | E31: 3611 | F31: 5.5659 | G31: 49.37 | H31: =IF(F31=0,"Yes","No") -> No | I31: 76.79 | J31: 91.63 | K31: 60.92
A32: 3 | B32: 8 | C32: 0.56 | D32: 83.94 | E32: 3659 | F32: 28.8668 | G32: 59.71 | H32: =IF(F32=0,"Yes","No") -> No | I32: 91.63 | J32: 67.08 | K32: 33.09
A33: 4 | B33: 5 | C33: 0.96 | D33: 64.04 | E33: 1879 | F33: 10.3567 | G33: 57.41 | H33: =IF(F33=0,"Yes","No") -> No | I33: 77.84 | J33: 86.2 | K33: 47.98
A34: 5 | B34: 5 | C34: 1.24 | D34: 51.98 | E34: 4981 | F34: 6.594 | G34: 48.55 | H34: =IF(F34=0,"Yes","No") -> No | I34: 74.45 | J34: 91.42 | K34: 65.55
A35: 6 | H35: =IF(F35=0,"Yes","No") -> Yes
A36: 7 | H36: =IF(F36=0,"Yes","No") -> Yes
A37: 8 | H37: =IF(F37=0,"Yes","No") -> Yes
A38: 9 | H38: =IF(F38=0,"Yes","No") -> Yes
A39: 10 | H39: =IF(F39=0,"Yes","No") -> Yes
A41: avg | B41: =AVERAGE(B30:B39) -> 5.6 | C41: =AVERAGE(C30:C39) -> 0.928 | D41: =AVERAGE(D30:D39) -> 59.46 | E41: =AVERAGE(E30:E39) -> 3615.8 | F41: =AVERAGE(F30:F39) -> 10.77146 | G41: =AVERAGE(G30:G39) -> 51.796 | H41: =(COUNTIF(H30:H39,"Yes")/10)*100 -> 50 | I41: =AVERAGE(I30:I39) -> 80.92 | J41: =AVERAGE(J30:J39) -> 85.282 | K41: =AVERAGE(K30:K39) -> 50.866 | L41: =AVERAGE(L30:L39) -> #DIV/0!
F42: =((D41-G41)/D41)*100 -> 12.889337

Sheet 3_scenario_a5
A1: bins J (1° stage) | B1: 7 | C1: 11 | D1: 13 | E1: 14 | F1: 15 | G1: 16 | H1: 17 | I1: 21 | N1: # fixed bins | O1: OF | P1: Time | Q1: Gap | R1: LB
A2: deterministic solution | N2: 8 | O2: 78.97 | P2: 900 | Q2: 0.2335 | R2: 60.53
A3: EVP
O6: VSS%
O7: =((ABS(C25-D41))/D41)*100 -> 22.722494
A13: zEVP | B13: # bins extra | C13: OF | D13: time_execution | E13: Gap | F13: LB | G13: Optimality reached? | H13: O_fs | I13: F_fs | J13: F_ss | K13: #items
A14: 1 | B14: 0 | C14: 78.97 | D14: 0.15081 | E14: 0 | F14: 78.97 | G14: =IF(E14=0,"Yes","No") -> Yes | H14: 100 | I14: 60.93
A15: 2 | B15: 0 | C15: 78.97 | D15: 0.07245 | E15: 0 | F15: 78.97 | G15: =IF(E15=0,"Yes","No") -> Yes | H15: 100 | I15: 57.44
A16: 3 | B16: 0 | C16: 78.97 | D16: 0.06228 | E16: 0 | F16: 78.97 | G16: =IF(E16=0,"Yes","No") -> Yes | H16: 100 | I16: 55.64
A17: 4 | B17: 1.33 | C17: 90.23 | D17: 1867.7201 | E17: 3.7033 | F17: 86.88 | G17: =IF(E17=0,"Yes","No") -> No | H17: 87.52 | I17: 70.11 | J17: 35.63
A18: 5 | B18: 0.33 | C18: 81.44 | D18: 6.6954 | E18: 0 | F18: 81.44 | G18: =IF(E18=0,"Yes","No") -> Yes | H18: 96.96 | I18: 55.18 | J18: 13.53
A19: 6 | G19: =IF(E19=0,"Yes","No") -> Yes
A20: 7 | G20: =IF(E20=0,"Yes","No") -> Yes
A21: 8 | G21: =IF(E21=0,"Yes","No") -> Yes
A22: 9 | G22: =IF(E22=0,"Yes","No") -> Yes
A23: 10 | G23: =IF(E23=0,"Yes","No") -> Yes
A25: avg | B25: =AVERAGE(B14:B23) -> 0.332 | C25: =AVERAGE(C14:C23) -> 81.716 | D25: =AVERAGE(D14:D23) -> 374.94021 | E25: =AVERAGE(E14:E23) -> 0.74066 | F25: =AVERAGE(F14:F23) -> 81.046 | G25: =(COUNTIF(G14:G23,"Yes")/10)*100 -> 90 | H25: =AVERAGE(H14:H23) -> 96.896 | I25: =AVERAGE(I14:I23) -> 59.86 | J25: =AVERAGE(J14:J23) -> 24.58 | K25: =AVERAGE(K14:K23) -> #DIV/0!
E26: =((C25-F25)/C25)*100 -> 0.81991287
A29: Stochastic 2 stage | B29: # fixed bins | C29: bins extra | D29: OF | E29: time_execution | F29: Gap | G29: LB | H29: Optimality reached? | I29: O_fs | J29: F_fs | K29: F_ss | L29: # items
A30: 1 | B30: 6 | C30: 1 | D30: 70.97 | E30: 1868 | F30: 32.0652 | G30: 4.82 | H30: =IF(F30=0,"Yes","No") -> No | I30: 73.49 | J30: 61.94 | K30: 57.08
A31: 2 | B31: 8 | C31: 2 | D31: 67.94 | E31: 2548 | F31: 27.3301 | G31: 49.37 | H31: =IF(F31=0,"Yes","No") -> No | I31: 75.55 | J31: 71.06 | K31: 65.41
A32: 3 | B32: 6 | C32: 0.67 | D32: 53.87 | E32: 1933 | F32: 30.3844 | G32: 37.5 | H32: =IF(F32=0,"Yes","No") -> No | I32: 74.63 | J32: 52.73 | K32: 43.53
A33: 4 | B33: 8 | C33: 2.33 | D33: 84.43 | E33: 2276 | F33: 31.8995 | G33: 57.5 | H33: =IF(F33=0,"Yes","No") -> No | I33: 69.03 | J33: 70.44 | K33: 73.54
A34: 5 | B34: 4 | C34: 3 | D34: 55.72 | E34: 1800 | F34: 36.5975 | G34: 35.33 | H34: =IF(F34=0,"Yes","No") -> No | I34: 59.46 | J34: 66.91 | K34: 63.7
A35: 6 | H35: =IF(F35=0,"Yes","No") -> Yes
A36: 7 | H36: =IF(F36=0,"Yes","No") -> Yes
A37: 8 | H37: =IF(F37=0,"Yes","No") -> Yes
A38: 9 | H38: =IF(F38=0,"Yes","No") -> Yes
A39: 10 | H39: =IF(F39=0,"Yes","No") -> Yes
A41: avg | B41: =AVERAGE(B30:B39) -> 6.4 | C41: =AVERAGE(C30:C39) -> 1.8 | D41: =AVERAGE(D30:D39) -> 66.586 | E41: =AVERAGE(E30:E39) -> 2085 | F41: =AVERAGE(F30:F39) -> 31.65534 | G41: =AVERAGE(G30:G39) -> 36.904 | H41: =(COUNTIF(H30:H39,"Yes")/10)*100 -> 50 | I41: =AVERAGE(I30:I39) -> 70.432 | J41: =AVERAGE(J30:J39) -> 64.616 | K41: =AVERAGE(K30:K39) -> 60.652 | L41: =AVERAGE(L30:L39) -> #DIV/0!
F42: =((D41-G41)/D41)*100 -> 44.576938

Sheet 10_scenario_a5
A1: bins J (1° stage) | B1: 7 | C1: 11 | D1: 13 | E1: 14 | F1: 15 | G1: 16 | H1: 17 | I1: 21 | N1: # fixed bins | O1: OF | P1: Time | Q1: Gap | R1: LB
A2: deterministic solution | N2: 8 | O2: 78.97 | P2: 900 | Q2: 0.2335 | R2: 60.53
A3: EVP
O6: VSS%
O7: =((ABS(C25-D41))/D41)*100 -> 15.166885
A13: zEVP | B13: # bins extra | C13: OF | D13: time_execution | E13: Gap | F13: LB | G13: Optimality reached? | H13: O_fs | I13: F_fs | J13: F_ss | K13: #items
A14: 1 | B14: 0.3 | C14: 81.6 | D14: 473.66 | E14: 0.9097 | F14: 80.86 | G14: =IF(E14=0,"Yes","No") -> No | H14: 96.77 | I14: 60.46 | J14: 9.94
A15: 2 | B15: 0.5 | C15: 83.5 | D15: 1800 | E15: 1.377 | F15: 82.35 | G15: =IF(E15=0,"Yes","No") -> No | H15: 94.58 | I15: 59.44 | J15: 23.85
A16: 3 | B16: 0.8 | C16: 86.54 | D16: 3057 | E16: 5.442 | F16: 81.83 | G16: =IF(E16=0,"Yes","No") -> No | H16: 91.25 | I16: 59.12 | J16: 28.05
A17: 4 | B17: 0.7 | C17: 84.98 | D17: 1800 | E17: 2.1058 | F17: 83.19 | G17: =IF(E17=0,"Yes","No") -> No | H17: 92.93 | I17: 63.27 | J17: 23.87
A18: 5 | B18: 0.8 | C18: 85.72 | D18: 1800 | E18: 3.4639 | F18: 82.75 | G18: =IF(E18=0,"Yes","No") -> No | H18: 92.12 | I18: 61.92 | J18: 26.7
A19: 6 | G19: =IF(E19=0,"Yes","No") -> Yes
A20: 7 | G20: =IF(E20=0,"Yes","No") -> Yes
A21: 8 | G21: =IF(E21=0,"Yes","No") -> Yes
A22: 9 | G22: =IF(E22=0,"Yes","No") -> Yes
A23: 10 | G23: =IF(E23=0,"Yes","No") -> Yes
A25: avg | B25: =AVERAGE(B14:B23) -> 0.62 | C25: =AVERAGE(C14:C23) -> 84.468 | D25: =AVERAGE(D14:D23) -> 1786.132 | E25: =AVERAGE(E14:E23) -> 2.65968 | F25: =AVERAGE(F14:F23) -> 82.196 | G25: =(COUNTIF(G14:G23,"Yes")/10)*100 -> 50 | H25: =AVERAGE(H14:H23) -> 93.53 | I25: =AVERAGE(I14:I23) -> 60.842 | J25: =AVERAGE(J14:J23) -> 22.482 | K25: =AVERAGE(K14:K23) -> #DIV/0!
E26: =((C25-F25)/C25)*100 -> 2.689776
A29: Stochastic 2 stage | B29: # fixed bins | C29: bins extra | D29: OF | E29: time_execution | F29: Gap | G29: LB | H29: Optimality reached? | I29: O_fs | J29: F_fs | K29: F_ss | L29: # items
A30: 1 | B30: 5 | C30: 2.5 | D30: 76.54 | E30: 2577 | F30: 33.8587 | G30: 50.62 | H30: =IF(F30=0,"Yes","No") -> No | I30: 68.14 | J30: 60.27 | K30: 58.89
A31: 2 | B31: 7 | C31: 2.8 | D31: 78.64 | E31: 1800 | F31: 31.3317 | G31: 53.4 | H31: =IF(F31=0,"Yes","No") -> No | I31: 76.49 | J31: 71.05 | K31: 57.55
A32: 3 | B32: 6 | C32: 2 | D32: 65.53 | E32: 2265 | F32: 32.8629 | G32: 43.4 | H32: =IF(F32=0,"Yes","No") -> No | I32: 73.61 | J32: 55.24 | K32: 40.17
A33: 4 | B33: 5 | C33: 3.5 | D33: 76.75 | E33: 1800 | F33: 33.5294 | G33: 51.02 | H33: =IF(F33=0,"Yes","No") -> No | I33: 65.8 | J33: 63.87 | K33: 61.8
A34: 5 | B34: 7 | C34: 2.5 | D34: 69.26 | E34: 2077 | F34: 40.0689 | G34: 41.51 | H34: =IF(F34=0,"Yes","No") -> No | I34: 72.19 | J34: 64.34 | K34: 58.23
A35: 6 | H35: =IF(F35=0,"Yes","No") -> Yes
A36: 7 | H36: =IF(F36=0,"Yes","No") -> Yes
A37: 8 | H37: =IF(F37=0,"Yes","No") -> Yes
A38: 9 | H38: =IF(F38=0,"Yes","No") -> Yes
A39: 10 | H39: =IF(F39=0,"Yes","No") -> Yes
A41: avg | B41: =AVERAGE(B30:B39) -> 6 | C41: =AVERAGE(C30:C39) -> 2.66 | D41: =AVERAGE(D30:D39) -> 73.344 | E41: =AVERAGE(E30:E39) -> 2103.8 | F41: =AVERAGE(F30:F39) -> 34.33032 | G41: =AVERAGE(G30:G39) -> 47.99 | H41: =(COUNTIF(H30:H39,"Yes")/10)*100 -> 50 | I41: =AVERAGE(I30:I39) -> 71.246 | J41: =AVERAGE(J30:J39) -> 62.954 | K41: =AVERAGE(K30:K39) -> 55.328 | L41: =AVERAGE(L30:L39) -> #DIV/0!
F42: =((D41-G41)/D41)*100 -> 34.568608

Sheet 3_scenarios
A1: bins J (1° stage) | B1: 7 | C1: 11 | D1: 13 | E1: 14 | F1: 15 | G1: 16 | H1: 17 | I1: 21 | N1: # fixed bins | O1: OF | P1: Time | Q1: Gap | R1: LB
A2: deterministic solution | N2: 8 | O2: 78.97 | P2: 900 | Q2: 0.2335 | R2: 60.53
A3: EVP
O6: VSS%
O7: =((ABS(C25-D41))/D41)*100 -> 6.5172776
A13: zEVP | B13: # bins extra | C13: OF | D13: time_execution | E13: Gap | F13: LB | G13: Optimality reached? | H13: O_fs | I13: F_fs | J13: F_ss | K13: #items
A14: 1 | B14: 0.67 | C14: 85.57 | D14: 12.99 | E14: 0 | F14: 85.57 | G14: =IF(E14=0,"Yes","No") -> Yes | H14: 92.29 | I14: 69.86 | J14: 37.31
A15: 2 | B15: 0.33 | C15: 82.27 | D15: 3.27 | E15: 0 | F15: 82.27 | G15: =IF(E15=0,"Yes","No") -> Yes | H15: 95.99 | I15: 58.47 | J15: 23.73
A16: 3 | B16: 0.67 | C16: 87.38 | D16: 2421.78 | E16: 3.7759 | F16: 84.08 | G16: =IF(E16=0,"Yes","No") -> No | H16: 90.38 | I16: 64.18 | J16: 18.68
A17: 4 | B17: 0.67 | C17: 87.38 | D17: 5010 | E17: 6.9289 | F17: 81.32 | G17: =IF(E17=0,"Yes","No") -> No | H17: 90.38 | I17: 60.65 | J17: 20.19
A18: 5 | B18: 2 | C18: 103.75 | D18: 5259 | E18: 23.8878 | F18: 78.97 | G18: =IF(E18=0,"Yes","No") -> No | H18: 76.11 | I18: 69 | J18: 41.93
A19: 6 | G19: =IF(E19=0,"Yes","No") -> Yes
A20: 7 | G20: =IF(E20=0,"Yes","No") -> Yes
A21: 8 | G21: =IF(E21=0,"Yes","No") -> Yes
A22: 9 | G22: =IF(E22=0,"Yes","No") -> Yes
A23: 10 | G23: =IF(E23=0,"Yes","No") -> Yes
A25: avg | B25: =AVERAGE(B14:B23) -> 0.868 | C25: =AVERAGE(C14:C23) -> 89.27 | D25: =AVERAGE(D14:D23) -> 2541.408 | E25: =AVERAGE(E14:E23) -> 6.91852 | F25: =AVERAGE(F14:F23) -> 82.442 | G25: =(COUNTIF(G14:G23,"Yes")/10)*100 -> 70 | H25: =AVERAGE(H14:H23) -> 89.03 | I25: =AVERAGE(I14:I23) -> 64.432 | J25: =AVERAGE(J14:J23) -> 28.368 | K25: =AVERAGE(K14:K23) -> #DIV/0!
E26: =((C25-F25)/C25)*100 -> 7.6487062
A29: Stochastic 2 stage | B29: # fixed bins | C29: bins extra | D29: OF | E29: time_execution | F29: Gap | G29: LB | H29: Optimality reached? | I29: O_fs | J29: F_fs | K29: F_ss | L29: # items
A30: 1 | B30: 8 | C30: 0.33 | D30: 67.21 | E30: 2137 | F30: 30.8171 | G30: 46.5 | H30: =IF(F30=0,"Yes","No") -> No | I30: 94.97 | J30: 60.36 | K30: 3.56
A31: 2 | B31: 6 | C31: 1.33 | D31: 61.63 | E31: 2653 | F31: 34.5426 | G31: 40.34 | H31: =IF(F31=0,"Yes","No") -> No | I31: 78.86 | J31: 61.6 | K31: 52.16
A32: 3 | B32: 8 | C32: 1 | D32: 76.41 | E32: 2007 | F32: 37.9045 | G32: 47.45 | H32: =IF(F32=0,"Yes","No") -> No | I32: 88.49 | J32: 61.16 | K32: 16.67
A33: 4 | B33: 8 | C33: 1 | D33: 97.46 | E33: 1811 | F33: 36.3969 | G33: 61.99 | H33: =IF(F33=0,"Yes","No") -> No | I33: 85.06 | J33: 62.11 | K33: 18.44
A34: 5 | B34: 9 | C34: 1.33 | D34: 116.33 | E34: 1899 | F34: 35.1325 | G34: 75.46 | H34: =IF(F34=0,"Yes","No") -> No | I34: 83.63 | J34: 61.62 | K34: 44.25
A35: 6 | H35: =IF(F35=0,"Yes","No") -> Yes
A36: 7 | H36: =IF(F36=0,"Yes","No") -> Yes
A37: 8 | H37: =IF(F37=0,"Yes","No") -> Yes
A38: 9 | H38: =IF(F38=0,"Yes","No") -> Yes
A39: 10 | H39: =IF(F39=0,"Yes","No") -> Yes
A41: avg | B41: =AVERAGE(B30:B39) -> 7.8 | C41: =AVERAGE(C30:C39) -> 0.998 | D41: =AVERAGE(D30:D39) -> 83.808 | E41: =AVERAGE(E30:E39) -> 2101.4 | F41: =AVERAGE(F30:F39) -> 34.95872 | G41: =AVERAGE(G30:G39) -> 54.348 | H41: =(COUNTIF(H30:H39,"Yes")/10)*100 -> 50 | I41: =AVERAGE(I30:I39) -> 86.202 | J41: =AVERAGE(J30:J39) -> 61.37 | K41: =AVERAGE(K30:K39) -> 27.016 | L41: =AVERAGE(L30:L39) -> #DIV/0!
F42: =((D41-G41)/D41)*100 -> 35.151775

Sheet 10_scenarios
A1: bins J (1° stage) | B1: 7 | C1: 11 | D1: 13 | E1: 14 | F1: 15 | G1: 16 | H1: 17 | I1: 21 | N1: # fixed bins | O1: OF | P1: Time | Q1: Gap | R1: LB
A2: deterministic solution | N2: 8 | O2: 78.97 | P2: 900 | Q2: 0.2335 | R2: 60.53
A3: EVP
O6: VSS%
O7: =((ABS(C25-D41))/D41)*100 -> 6.5942401
A13: zEVP | B13: # bins extra | C13: OF | D13: time_execution | E13: Gap | F13: LB | G13: Optimality reached? | H13: O_fs | I13: F_fs | J13: F_ss | K13: #items
A14: 1 | B14: 0.6 | C14: 85.45 | D14: 727 | E14: 0.6357 | F14: 84.91 | G14: =IF(E14=0,"Yes","No") -> No | H14: 92.41 | I14: 63.63 | J14: 31.2
A15: 2 | B15: 0.4 | C15: 83.47 | D15: 5231 | E15: 1.4537 | F15: 82.26 | G15: =IF(E15=0,"Yes","No") -> No | H15: 94.61 | I15: 60.46 | J15: 18.87
A16: 3 | B16: 0.7 | C16: 87.53 | D16: 2462 | E16: 9.7776 | F16: 78.97 | G16: =IF(E16=0,"Yes","No") -> No | H16: 90.22 | I16: 64.65 | J16: 24.03
A17: 4 | B17: 0.5 | C17: 85.45 | D17: 4089 | E17: 7.5855 | F17: 78.97 | G17: =IF(E17=0,"Yes","No") -> No | H17: 92.41 | I17: 61.45 | J17: 16.84
A18: 5 | B18: 1.3 | C18: 93.74 | D18: 4815 | E18: 15.7601 | F18: 78.97 | G18: =IF(E18=0,"Yes","No") -> No | H18: 84.24 | I18: 63.95 | J18: 32.45
A19: 6 | G19: =IF(E19=0,"Yes","No") -> Yes
A20: 7 | G20: =IF(E20=0,"Yes","No") -> Yes
A21: 8 | G21: =IF(E21=0,"Yes","No") -> Yes
A22: 9 | G22: =IF(E22=0,"Yes","No") -> Yes
A23: 10 | G23: =IF(E23=0,"Yes","No") -> Yes
A25: avg | B25: =AVERAGE(B14:B23) -> 0.7 | C25: =AVERAGE(C14:C23) -> 87.128 | D25: =AVERAGE(D14:D23) -> 3464.8 | E25: =AVERAGE(E14:E23) -> 7.04252 | F25: =AVERAGE(F14:F23) -> 80.816 | G25: =(COUNTIF(G14:G23,"Yes")/10)*100 -> 50 | H25: =AVERAGE(H14:H23) -> 90.778 | I25: =AVERAGE(I14:I23) -> 62.828 | J25: =AVERAGE(J14:J23) -> 24.678 | K25: =AVERAGE(K14:K23) -> #DIV/0!
E26: =((C25-F25)/C25)*100 -> 7.2445138
A29: Stochastic 2 stage | B29: # fixed bins | C29: bins extra | D29: OF | E29: time_execution | F29: Gap | G29: LB | H29: Optimality reached? | I29: O_fs | J29: F_fs | K29: F_ss | L29: # items
A30: 1 | B30: 7 | C30: 1.1 | D30: 66.71 | E30: 2589 | F30: 32.8584 | G30: 44.79 | H30: =IF(F30=0,"Yes","No") -> No | I30: 82.58 | J30: 55.98 | K30: 42.65
A31: 2 | B31: 8 | C31: 0.7 | D31: 67.37 | E31: 1887 | F31: 38.379 | G31: 41.51 | H31: =IF(F31=0,"Yes","No") -> No | I31: 91.08 | J31: 57.31 | K31: 23.66
A32: 3 | B32: 8 | C32: 0.6 | D32: 75.27 | E32: 2454 | F32: 36.5017 | G32: 47.8 | H32: =IF(F32=0,"Yes","No") -> No | I32: 91.66 | J32: 59.96 | K32: 17.67
A33: 4 | B33: 8 | C33: 0.7 | D33: 95.77 | E33: 1800 | F33: 36.5806 | G33: 60.74 | H33: =IF(F33=0,"Yes","No") -> No | I33: 90.13 | J33: 58.46 | K33: 29.4
A34: 5 | B34: 8 | C34: 1.4 | D34: 103.57 | E34: 1800 | F34: 36.4175 | G34: 65.86 | H34: =IF(F34=0,"Yes","No") -> No | I34: 83.79 | J34: 61.09 | K34: 30.87
A35: 6 | H35: =IF(F35=0,"Yes","No") -> Yes
A36: 7 | H36: =IF(F36=0,"Yes","No") -> Yes
A37: 8 | H37: =IF(F37=0,"Yes","No") -> Yes
A38: 9 | H38: =IF(F38=0,"Yes","No") -> Yes
A39: 10 | H39: =IF(F39=0,"Yes","No") -> Yes
A41: avg | B41: =AVERAGE(B30:B39) -> 7.8 | C41: =AVERAGE(C30:C39) -> 0.9 | D41: =AVERAGE(D30:D39) -> 81.738 | E41: =AVERAGE(E30:E39) -> 2106 | F41: =AVERAGE(F30:F39) -> 36.14744 | G41: =AVERAGE(G30:G39) -> 52.14 | H41: =(COUNTIF(H30:H39,"Yes")/10)*100 -> 50 | I41: =AVERAGE(I30:I39) -> 87.848 | J41: =AVERAGE(J30:J39) -> 58.56 | K41: =AVERAGE(K30:K39) -> 28.85 | L41: =AVERAGE(L30:L39) -> #DIV/0!
F42: =((D41-G41)/D41)*100 -> 36.21082

Sheet sp1_25_a5
A1: bins J (1° stage) | B1: 7 | C1: 11 | D1: 13 | E1: 14 | F1: 15 | G1: 16 | H1: 17 | I1: 21 | N1: # fixed bins | O1: OF | P1: Time | Q1: Gap | R1: LB
A2: deterministic solution | N2: 8 | O2: 78.97 | P2: 900 | Q2: 0.2335 | R2: 60.53
A3: EVP
O6: VSS%
O7: =((ABS(C25-D41))/D41)*100 -> 15.254193
A13: zEVP | B13: # bins extra | C13: OF | D13: time_execution | E13: Gap | F13: LB | G13: Optimality reached? | H13: O_fs | I13: F_fs | J13: F_ss | K13: #items
A14: 1 | B14: 0.44 | C14: 82.89 | D14: 5905 | E14: 1.9494 | F14: 81.27 | G14: =IF(E14=0,"Yes","No") -> No | H14: 95.27 | I14: 62.05 | J14: 15.33
A15: 2 | B15: 0.8 | C15: 85.64 | D15: 1818 | E15: 7.7925 | F15: 78.97 | G15: =IF(E15=0,"Yes","No") -> No | H15: 92.21 | I15: 65.02 | J15: 28.71
A16: 3 | B16: 0.6 | C16: 83.87 | D16: 3494 | E16: 5.8458 | F16: 78.97 | G16: =IF(E16=0,"Yes","No") -> No | H16: 94.15 | I16: 62.67 | J16: 23.33
A17: 4 | B17: 1.32 | C17: 89.09 | D17: 3659 | E17: 11.3642 | F17: 78.97 | G17: =IF(E17=0,"Yes","No") -> No | H17: 88.64 | I17: 62.22 | J17: 25.99
A18: 5 | B18: 1.28 | C18: 88.47 | D18: 3659 | E18: 10.7402 | F18: 78.97 | G18: =IF(E18=0,"Yes","No") -> No | H18: 89.26 | I18: 59.57 | J18: 22.58
A19: 6 | B19: 1.28 | C19: 88.96 | D19: 3659 | E19: 11.2307 | F19: 78.97 | G19: =IF(E19=0,"Yes","No") -> No | H19: 88.77 | I19: 60.98 | J19: 29.56
A20: 7 | B20: 1.48 | C20: 89.96 | D20: 3659 | E20: 12.2134 | F20: 78.97 | G20: =IF(E20=0,"Yes","No") -> No | H20: 87.79 | I20: 61.07 | J20: 26.63
A21: 8 | B21: 1 | C21: 87.25 | D21: 3659 | E21: 9.4916 | F21: 78.97 | G21: =IF(E21=0,"Yes","No") -> No | H21: 90.51 | I21: 61.81 | J21: 27.55
A22: 9 | B22: 1.84 | C22: 92.87 | D22: 3474 | E22: 14.9721 | F22: 78.97 | G22: =IF(E22=0,"Yes","No") -> No | H22: 85.03 | I22: 63.47 | J22: 33.14
A23: 10 | B23: 0.76 | C23: 85.18 | D23: 3845 | E23: 7.2947 | F23: 78.97 | G23: =IF(E23=0,"Yes","No") -> No | H23: 92.71 | I23: 60.28 | J23: 22.97
A25: avg | B25: =AVERAGE(B14:B23) -> 1.08 | C25: =AVERAGE(C14:C23) -> 87.418 | D25: =AVERAGE(D14:D23) -> 3683.1 | E25: =AVERAGE(E14:E23) -> 9.28946 | F25: =AVERAGE(F14:F23) -> 79.2 | G25: =(COUNTIF(G14:G23,"Yes")/10)*100 -> 0 | H25: =AVERAGE(H14:H23) -> 90.434 | I25: =AVERAGE(I14:I23) -> 61.914 | J25: =AVERAGE(J14:J23) -> 25.579 | K25: =AVERAGE(K14:K23) -> #DIV/0!
E26: =((C25-F25)/C25)*100 -> 9.4008099
A29: Stochastic 2 stage | B29: # fixed bins | C29: bins extra | D29: OF | E29: time_execution | F29: Gap | G29: LB | H29: Optimality reached? | I29: O_fs | J29: F_fs | K29: F_ss | L29: # items
A30: 1 | B30: 6 | C30: 1.88 | D30: 80.77 | E30: 2045 | F30: 33.6895 | G30: 53.56 | H30: =IF(F30=0,"Yes","No") -> No | I30: 77.47 | J30: 57.67 | K30: 60.7
A31: 2 | B31: 7 | C31: 3.88 | D31: 84.14 | E31: 2197 | F31: 29.7246 | G31: 59.13 | H31: =IF(F31=0,"Yes","No") -> No | I31: 71.48 | J31: 71.26 | K31: 65.57
A32: 3 | B32: 6 | C32: 1.84 | D32: 63.94 | E32: 1800 | F32: 33.3468 | G32: 42.61 | H32: =IF(F32=0,"Yes","No") -> No | I32: 75.45 | J32: 55.73 | K32: 45.45
A33: 4 | B33: 7 | C33: 2.52 | D33: 76.18 | E33: 1800 | F33: 34.6929 | G33: 49.75 | H33: =IF(F33=0,"Yes","No") -> No | I33: 71.07 | J33: 69.85 | K33: 53.85
A34: 5 | B34: 7 | C34: 2.76 | D34: 69.06 | E34: 2169 | F34: 42.3331 | G34: 39.82 | H34: =IF(F34=0,"Yes","No") -> No | I34: 69.98 | J34: 67.46 | K34: 62.03
A35: 6 | B35: 6 | C35: 2.88 | D35: 93.19 | E35: 1800 | F35: 35.3526 | G35: 60.25 | H35: =IF(F35=0,"Yes","No") -> No | I35: 68.52 | J35: 68.41 | K35: 64.06
A36: 7 | B36: 6 | C36: 1.96 | D36: 84.95 | E36: 1884 | F36: 33.0809 | G36: 56.85 | H36: =IF(F36=0,"Yes","No") -> No | I36: 76.7 | J36: 56.82 | K36: 51.94
A37: 8 | B37: 7 | C37: 2.12 | D37: 70.7 | E37: 1800 | F37: 38.6741 | G37: 43.36 | H37: =IF(F37=0,"Yes","No") -> No | I37: 76.07 | J37: 63.27 | K37: 53.31
A38: 9 | B38: 4 | C38: 4.64 | D38: 69.54 | E38: 1800 | F38: 33.0615 | G38: 46.55 | H38: =IF(F38=0,"Yes","No") -> No | I38: 48.89 | J38: 66.96 | K38: 57.86
A39: 10 | B39: 6 | C39: 1.8 | D39: 66.01 | E39: 2462 | F39: 34.0305 | G39: 43.55 | H39: =IF(F39=0,"Yes","No") -> No | I39: 77.98 | J39: 57.59 | K39: 45.61
A41: avg | B41: =AVERAGE(B30:B39) -> 6.2 | C41: =AVERAGE(C30:C39) -> 2.628 | D41: =AVERAGE(D30:D39) -> 75.848 | E41: =AVERAGE(E30:E39) -> 1975.7 | F41: =AVERAGE(F30:F39) -> 34.79865 | G41: =AVERAGE(G30:G39) -> 49.543 | H41: =(COUNTIF(H30:H39,"Yes")/10)*100 -> 0 | I41: =AVERAGE(I30:I39) -> 71.361 | J41: =AVERAGE(J30:J39) -> 63.502 | K41: =AVERAGE(K30:K39) -> 56.038 | L41: =AVERAGE(L30:L39) -> #DIV/0!
F42: =((D41-G41)/D41)*100 -> 34.681205

Sheet sp1_25_a10
A1: bins J (1° stage) | B1: 7 | C1: 11 | D1: 13 | E1: 14 | F1: 15 | G1: 16 | H1: 17 | I1: 21 | N1: # fixed bins | O1: OF | P1: Time | Q1: Gap | R1: LB
A2: deterministic solution | N2: 8 | O2: 78.97 | P2: 900 | Q2: 0.2335 | R2: 60.53
A3: EVP
O6: VSS%
O7: =((ABS(C25-D41))/D41)*100 -> 15.630463
A13: zEVP | B13: # bins extra | C13: OF | D13: time_execution | E13: Gap | F13: LB | G13: Optimality reached? | H13: O_fs | I13: F_fs | J13: F_ss | K13: #items
A14: 1 | B14: 0.64 | C14: 84.63 | D14: 3108 | E14: 2.86 | F14: 82.21 | G14: =IF(E14=0,"Yes","No") -> No | H14: 93.31 | I14: 61.69 | J14: 23.99
A15: 2 | B15: 0.6 | C15: 84.62 | D15: 1800 | E15: 2.8416 | F15: 82.21 | G15: =IF(E15=0,"Yes","No") -> No | H15: 93.32 | I15: 62.16 | J15: 21.57
A16: 3 | B16: 0.72 | C16: 85.59 | D16: 1800 | E16: 2.8992 | F16: 83.11 | G16: =IF(E16=0,"Yes","No") -> No | H16: 92.26 | I16: 66.15 | J16: 26.39
A17: 4 | B17: 0.56 | C17: 83.84 | D17: 1800 | E17: 1.5736 | F17: 82.52 | G17: =IF(E17=0,"Yes","No") -> No | H17: 94.19 | I17: 62.6 | J17: 25.16
A18: 5 | B18: 0.84 | C18: 87.13 | D18: 1800 | E18: 5.272 | F18: 82.53 | G18: =IF(E18=0,"Yes","No") -> No | H18: 90.64 | I18: 63.42 | J18: 24.97
A19: 6 | B19: 0.64 | C19: 84.97 | D19: 1800 | E19: 3.3046 | F19: 82.16 | G19: =IF(E19=0,"Yes","No") -> No | H19: 92.94 | I19: 63.17 | J19: 24.21
A20: 7 | B20: 0.56 | C20: 84.01 | D20: 1831 | E20: 1.5508 | F20: 82.7 | G20: =IF(E20=0,"Yes","No") -> No | H20: 94 | I20: 62.3 | J20: 24.06
A21: 8 | B21: 0.96 | C21: 87.97 | D21: 1889 | E21: 10.2332 | F21: 78.97 | G21: =IF(E21=0,"Yes","No") -> No | H21: 89.77 | I21: 65.17 | J21: 32.81
A22: 9 | B22: 0.64 | C22: 84.93 | D22: 1957 | E22: 5.2401 | F22: 80.48 | G22: =IF(E22=0,"Yes","No") -> No | H22: 92.98 | I22: 61.57 | J22: 26.3
A23: 10 | B23: 0.8 | C23: 86.56 | D23: 1800 | E23: 4.5442 | F23: 82.62 | G23: =IF(E23=0,"Yes","No") -> No | H23: 91.23 | I23: 62.69 | J23: 27.34
A25: avg | B25: =AVERAGE(B14:B23) -> 0.696 | C25: =AVERAGE(C14:C23) -> 85.425 | D25: =AVERAGE(D14:D23) -> 1958.5 | E25: =AVERAGE(E14:E23) -> 4.03193 | F25: =AVERAGE(F14:F23) -> 81.951 | G25: =(COUNTIF(G14:G23,"Yes")/10)*100 -> 0 | H25: =AVERAGE(H14:H23) -> 92.464 | I25: =AVERAGE(I14:I23) -> 63.092 | J25: =AVERAGE(J14:J23) -> 25.68 | K25: =AVERAGE(K14:K23) -> #DIV/0!
E26: =((C25-F25)/C25)*100 -> 4.0667252
A29: Stochastic 2 stage | B29: # fixed bins | C29: bins extra | D29: OF | E29: time_execution | F29: Gap | G29: LB | H29: Optimality reached? | I29: O_fs | J29: F_fs | K29: F_ss | L29: # items
A30: 1 | B30: 6 | C30: 1.92 | D30: 63.04 | E30: 3321 | F30: 34.4747 | G30: 41.3 | H30: =IF(F30=0,"Yes","No") -> No | I30: 74.91 | J30: 58.45 | K30: 45.67
A31: 2 | B31: 7 | C31: 3.8 | D31: 77.41 | E31: 5377 | F31: 46.8348 | G31: 41.15 | H31: =IF(F31=0,"Yes","No") -> No | I31: 69.36 | J31: 53.86 | K31: 59.44
A32: 3 | B32: 0 | C32: 16.64 | D32: 98.36 | E32: 3660 | F32: 52.3554 | G32: 46.86 | H32: =IF(F32=0,"Yes","No") -> No | I32: 0 | K32: 65.4
A33: 4 | B33: 6 | C33: 4.56 | D33: 104.57 | E33: 3660 | F33: 45.2735 | G33: 57.26 | H33: =IF(F33=0,"Yes","No") -> No | I33: 61.91 | J33: 58.14 | K33: 61.71
A34: 5 | B34: 0 | C34: 15.6 | D34: 126.74 | E34: 3660 | F34: 53.5636 | G34: 58.85 | H34: =IF(F34=0,"Yes","No") -> No | I34: 0 | K34: 66.15
A35: 6 | B35: 10 | C35: 0.88 | D35: 134.74 | E35: 3660 | F35: 54.8106 | G35: 60.89 | H35: =IF(F35=0,"Yes","No") -> No | I35: 90.96 | J35: 53.66 | K35: 43.27
A36: 7 | B36: 11 | C36: 2.48 | D36: 126.62 | E36: 3660 | F36: 50.8894 | G36: 62.18 | H36: =IF(F36=0,"Yes","No") -> No | I36: 79.18 | J36: 48.82 | K36: 38.47
A37: 8 | B37: 8 | C37: 4.08 | D37: 95.21 | E37: 3660 | F37: 54.0729 | G37: 43.73 | H37: =IF(F37=0,"Yes","No") -> No | I37: 63.43 | J37: 49.99 | K37: 58.19
A38: 9 | B38: 7 | C38: 3.88 | D38: 101.45 | E38: 3660 | F38: 49.8775 | G38: 50.85 | H38: =IF(F38=0,"Yes","No") -> No | I38: 66.03 | J38: 51.6 | K38: 65.21
A39: 10 | B39: 7 | C39: 2.2 | D39: 84.37 | E39: 3660 | F39: 46.9217 | G39: 44.78 | H39: =IF(F39=0,"Yes","No") -> No | I39: 74.25 | J39: 49.26 | K39: 39.28
A41: avg | B41: =AVERAGE(B30:B39) -> 6.2 | C41: =AVERAGE(C30:C39) -> 5.604 | D41: =AVERAGE(D30:D39) -> 101.251 | E41: =AVERAGE(E30:E39) -> 3797.8 | F41: =AVERAGE(F30:F39) -> 48.90741 | G41: =AVERAGE(G30:G39) -> 50.785 | H41: =(COUNTIF(H30:H39,"Yes")/10)*100 -> 0 | I41: =AVERAGE(I30:I39) -> 58.003 | J41: =AVERAGE(J30:J39) -> 52.9725 | K41: =AVERAGE(K30:K39) -> 54.279 | L41: =AVERAGE(L30:L39) -> #DIV/0!
F42: =((D41-G41)/D41)*100 -> 49.842471

Sheet sp1_25_a20
A1: bins J (1° stage) | B1: 7 | C1: 11 | D1: 13 | E1: 14 | F1: 15 | G1: 16 | H1: 17 | I1: 21 | N1: # fixed bins | O1: OF | P1: Time | Q1: Gap | R1: LB
A2: deterministic solution | N2: 8 | O2: 78.97 | P2: 900 | Q2: 0.2335 | R2: 60.53
A3: EVP
O6: VSS%
O7: =((ABS(C25-D41))/D41)*100 -> 0.16622754
A13: zEVP | B13: # bins extra | C13: OF | D13: time_execution | E13: Gap | F13: LB | G13: Optimality reached? | H13: O_fs | I13: F_fs | J13: F_ss | K13: #items
A14: 1 | B14: 1.12 | C14: 90.15 | D14: 1824 | E14: 5.8371 | F14: 84.89 | G14: =IF(E14=0,"Yes","No") -> No | H14: 87.6 | I14: 65.33 | J14: 43.24
A15: 2 | B15: 0.96 | C15: 88.79 | D15: 1800 | E15: 5.4656 | F15: 83.94 | G15: =IF(E15=0,"Yes","No") -> No | H15: 88.94 | I15: 62.71 | J15: 30.85
A16: 3 | B16: 0.48 | C16: 83.79 | D16: 6696 | E16: 1.9935 | F16: 82.12 | G16: =IF(E16=0,"Yes","No") -> No | H16: 94.25 | I16: 61.36 | J16: 20.27
A17: 4 | B17: 0.56 | C17: 84.61 | D17: 5029 | E17: 6.6622 | F17: 78.97 | G17: =IF(E17=0,"Yes","No") -> No | H17: 93.34 | I17: 60.53 | J17: 17.91
A18: 5 | B18: 1.64 | C18: 93.02 | D18: 2975 | E18: 15.1083 | F18: 78.97 | G18: =IF(E18=0,"Yes","No") -> No | H18: 84.89 | I18: 61.9 | J18: 28.76
A19: 6 | B19: 0.4 | C19: 82.74 | D19: 2776 | E19: 4.5519 | F19: 78.97 | G19: =IF(E19=0,"Yes","No") -> No | H19: 95.45 | I19: 61.7 | J19: 21.09
A20: 7 | B20: 0.56 | C20: 84.65 | D20: 5226 | E20: 6.7125 | F20: 78.97 | G20: =IF(E20=0,"Yes","No") -> No | H20: 93.29 | I20: 62.2 | J20: 22.39
A21: 8 | B21: 2.12 | C21: 98.32 | D21: 43.26 | E21: 19.682 | F21: 78.97 | G21: =IF(E21=0,"Yes","No") -> No | H21: 80.32 | I21: 62.17 | J21: 43.26
A22: 9 | B22: 0.6 | C22: 84.99 | D22: 2552 | E22: 5.743 | F22: 80.11 | G22: =IF(E22=0,"Yes","No") -> No | H22: 92.92 | I22: 62.28 | J22: 23.3
A23: 10 | B23: 1.44 | C23: 91.8 | D23: 1083 | E23: 13.9715 | F23: 78.97 | G23: =IF(E23=0,"Yes","No") -> No | H23: 86.03 | I23: 63.78 | J23: 27.98
A25: avg | B25: =AVERAGE(B14:B23) -> 0.988 | C25: =AVERAGE(C14:C23) -> 88.286 | D25: =AVERAGE(D14:D23) -> 3000.426 | E25: =AVERAGE(E14:E23) -> 8.57276 | F25: =AVERAGE(F14:F23) -> 80.488 | G25: =(COUNTIF(G14:G23,"Yes")/10)*100 -> 0 | H25: =AVERAGE(H14:H23) -> 89.703 | I25: =AVERAGE(I14:I23) -> 62.396 | J25: =AVERAGE(J14:J23) -> 27.905 | K25: =AVERAGE(K14:K23) -> #DIV/0!
E26: =((C25-F25)/C25)*100 -> 8.8326575
A29: Stochastic 2 stage | B29: # fixed bins | C29: bins extra | D29: OF | E29: time_execution | F29: Gap | G29: LB | H29: Optimality reached? | I29: O_fs | J29: F_fs | K29: F_ss | L29: # items
A30: 1 | B30: 9 | C30: 1.44 | D30: 83.13 | E30: 2219 | F30: 34.6991 | G30: 54.29 | H30: =IF(F30=0,"Yes","No") -> No | I30: 82.93 | J30: 67.23 | K30: 51.27
A31: 2 | B31: 6 | C31: 5.4 | D31: 112.43 | E31: 4337 | F31: 47.1556 | G31: 59.41 | H31: =IF(F31=0,"Yes","No") -> No | I31: 55.18 | J31: 56.34 | K31: 61.75
A32: 3 | B32: 7 | C32: 1.64 | D32: 74.41 | E32: 1800 | F32: 39.5593 | G32: 44.97 | H32: =IF(F32=0,"Yes","No") -> No | I32: 75.63 | J32: 57.46 | K32: 51.39
A33: 4 | B33: 8 | C33: 1.04 | D33: 80.62 | E33: 1800 | F33: 40.9389 | G33: 47.61 | H33: =IF(F33=0,"Yes","No") -> No | I33: 86.93 | J33: 56.19 | K33: 40.06
A34: 5 | B34: 7 | C34: 1.32 | D34: 84.75 | E34: 1800 | F34: 34.1571 | G34: 55.8 | H34: =IF(F34=0,"Yes","No") -> No | I34: 85.24 | J34: 56.58 | K34: 40.09
A35: 6 | B35: 7 | C35: 1.44 | D35: 76.37 | E35: 1800 | F35: 37.5078 | G35: 47.72 | H35: =IF(F35=0,"Yes","No") -> No | I35: 80.02 | J35: 60.18 | K35: 49.62
A36: 7 | B36: 6 | C36: 3 | D36: 69.89 | E36: 1800 | F36: 33.9957 | G36: 46.13 | H36: =IF(F36=0,"Yes","No") -> No | I36: 62.41 | J36: 70.93 | K36: 61.73
A37: 8 | B37: 14 | C37: 2.88 | D37: 95.33 | E37: 1924 | F37: 34.594 | G37: 62.35 | H37: =IF(F37=0,"Yes","No") -> No | I37: 77.39 | J37: 66.05 | K37: 48.24
A38: 9 | B38: 9 | C38: 2.44 | D38: 120.09 | E38: 2103 | F38: 48.3894 | G38: 61.98 | H38: =IF(F38=0,"Yes","No") -> No | I38: 79.36 | J38: 57.07 | K38: 48.13
A39: 10 | B39: 6 | C39: 3.6 | D39: 87.31 | E39: 3072 | F39: 49.1657 | G39: 44.38 | H39: =IF(F39=0,"Yes","No") -> No | I39: 60.27 | J39: 48.96 | K39: 45.81
A41: avg | B41: =AVERAGE(B30:B39) -> 7.9 | C41: =AVERAGE(C30:C39) -> 2.42 | D41: =AVERAGE(D30:D39) -> 88.433 | E41: =AVERAGE(E30:E39) -> 2265.5 | F41: =AVERAGE(F30:F39) -> 40.01626 | G41: =AVERAGE(G30:G39) -> 52.464 | H41: =(COUNTIF(H30:H39,"Yes")/10)*100 -> 0 | I41: =AVERAGE(I30:I39) -> 74.536 | J41: =AVERAGE(J30:J39) -> 59.699 | K41: =AVERAGE(K30:K39) -> 49.809 | L41: =AVERAGE(L30:L39) -> #DIV/0!
F42: =((D41-G41)/D41)*100 -> 40.67373

Sheet sp1_25_a40
A1: bins J (1° stage) | B1: 7 | C1: 11 | D1: 13 | E1: 14 | F1: 15 | G1: 16 | H1: 17 | I1: 21 | N1: # fixed bins | O1: OF | P1: Time | Q1: Gap | R1: LB
A2: deterministic solution | N2: 8 | O2: 78.97 | P2: 900 | Q2: 0.2335 | R2: 60.53
A3: EVP
O6: VSS%
O7: =((ABS(C25-D41))/D41)*100 -> 2.4981648
A13: zEVP | B13: # bins extra | C13: OF | D13: time_execution | E13: Gap | F13: LB | G13: Optimality reached? | H13: O_fs | I13: F_fs | J13: F_ss | K13: #items
A14: 1 | B14: 0.56 | C14: 85.16 | D14: 2860 | E14: 2.2356 | F14: 83.26 | G14: =IF(E14=0,"Yes","No") -> No | H14: 92.73 | I14: 62.01 | J14: 23.38
A15: 2 | B15: 1.8 | C15: 96.79 | D15: 4698 | E15: 18.408 | F15: 78.97 | G15: =IF(E15=0,"Yes","No") -> No | H15: 81.59 | I15: 64.2 | J15: 33.48
A16: 3 | B16: 1.04 | C16: 90.24 | D16: 3659 | E16: 12.4927 | F16: 78.97 | G16: =IF(E16=0,"Yes","No") -> No | H16: 87.51 | I16: 63.31 | J16: 29.41
A17: 4 | B17: 1.2 | C17: 92.04 | D17: 3659 | E17: 14.2049 | F17: 78.97 | G17: =IF(E17=0,"Yes","No") -> No | H17: 85.8 | I17: 61.24 | J17: 27.08
A18: 5 | B18: 1.16 | C18: 92.57 | D18: 2276 | E18: 14.6928 | F18: 78.97 | G18: =IF(E18=0,"Yes","No") -> No | H18: 85.31 | I18: 64.36 | J18: 33.62
A19: 6 | B19: 0.72 | C19: 87.13 | D19: 4155 | E19: 9.3651 | F19: 78.97 | G19: =IF(E19=0,"Yes","No") -> No | H19: 90.63 | I19: 62.72 | J19: 29.38
A20: 7 | B20: 0.88 | C20: 88.5 | D20: 4547 | E20: 10.7645 | F20: 78.97 | G20: =IF(E20=0,"Yes","No") -> No | H20: 89.24 | I20: 59.1 | J20: 25
A21: 8 | B21: 0.6 | C21: 85.89 | D21: 2679 | E21: 8.0555 | F21: 78.97 | G21: =IF(E21=0,"Yes","No") -> No | H21: 91.94 | I21: 61.16 | J21: 17.64
A22: 9 | B22: 0.68 | C22: 87 | D22: 2702 | E22: 4.6838 | F22: 82.93 | G22: =IF(E22=0,"Yes","No") -> No | H22: 90.77 | I22: 61.11 | J22: 25.33
A23: 10 | B23: 0.8 | C23: 88.3 | D23: 2005 | E23: 10.5692 | F23: 78.97 | G23: =IF(E23=0,"Yes","No") -> No | H23: 89.43 | I23: 61.44 | J23: 25.92
A25: avg | B25: =AVERAGE(B14:B23) -> 0.944 | C25: =AVERAGE(C14:C23) -> 89.362 | D25: =AVERAGE(D14:D23) -> 3324 | E25: =AVERAGE(E14:E23) -> 10.54721 | F25: =AVERAGE(F14:F23) -> 79.795 | G25: =(COUNTIF(G14:G23,"Yes")/10)*100 -> 0 | H25: =AVERAGE(H14:H23) -> 88.495 | I25: =AVERAGE(I14:I23) -> 62.065 | J25: =AVERAGE(J14:J23) -> 27.024 | K25: =AVERAGE(K14:K23) -> #DIV/0!
E26: =((C25-F25)/C25)*100 -> 10.705893
A29: Stochastic 2 stage | B29: # fixed bins | C29: bins extra | D29: OF | E29: time_execution | F29: Gap | G29: LB | H29: Optimality reached? | I29: O_fs | J29: F_fs | K29: F_ss | L29: # items
A30: 1 | B30: 8 | C30: 1.04 | D30: 69.62 | E30: 1907 | F30: 37.5862 | G30: 43.45 | H30: =IF(F30=0,"Yes","No") -> No | I30: 86.86 | J30: 59.03 | K30: 32.61
A31: 2 | B31: 9 | C31: 1.36 | D31: 83.28 | E31: 1890 | F31: 40.8312 | G31: 49.27 | H31: =IF(F31=0,"Yes","No") -> No | I31: 86.78 | J31: 56.74 | K31: 35.4
A32: 3 | B32: 8 | C32: 0.8 | D32: 100.73 | E32: 1955 | F32: 39.762 | G32: 60.68 | H32: =IF(F32=0,"Yes","No") -> No | I32: 90.06 | J32: 51.94 | K32: 26.72
A33: 4 | B33: 9 | C33: 0.56 | D33: 102.06 | E33: 1806 | F33: 43.7573 | G33: 57.4 | H33: =IF(F33=0,"Yes","No") -> No | I33: 92.09 | J33: 51.37 | K33: 21.01
A34: 5 | B34: 10 | C34: 0.64 | D34: 84.66 | E34: 2004 | F34: 42.7909 | G34: 48.44 | H34: =IF(F34=0,"Yes","No") -> No | I34: 91.42 | J34: 53.79 | K34: 27.01
A35: 6 | B35: 9 | C35: 0.56 | D35: 99.16 | E35: 1800 | F35: 40.3897 | G35: 59.11 | H35: =IF(F35=0,"Yes","No") -> No | I35: 91.49 | J35: 55.38 | K35: 23.03
A36: 7 | B36: 8 | C36: 1.12 | D36: 82.81 | E36: 1800 | F36: 36.1469 | G36: 52.88 | H36: =IF(F36=0,"Yes","No") -> No | I36: 85.63 | J36: 61.27 | K36: 31.58
A37: 8 | B37: 8 | C37: 1.44 | D37: 78.85 | E37: 2600 | F37: 35.3719 | G37: 50.96 | H37: =IF(F37=0,"Yes","No") -> No | I37: 80.61 | J37: 66.82 | K37: 38.65
A38: 9 | B38: 10 | C38: 0.4 | D38: 92.86 | E38: 2020 | F38: 42.0425 | G38: 53.82 | H38: =IF(F38=0,"Yes","No") -> No | I38: 96.1 | J38: 51.99 | K38: 15.94
A39: 10 | B39: 8 | C39: 0.72 | D39: 77.81 | E39: 1800 | F39: 40.6417 | G39: 46.19 | H39: =IF(F39=0,"Yes","No") -> No | I39: 90.06 | J39: 52.04 | K39: 16.89
A41: avg | B41: =AVERAGE(B30:B39) -> 8.7 | C41: =AVERAGE(C30:C39) -> 0.864 | D41: =AVERAGE(D30:D39) -> 87.184 | E41: =AVERAGE(E30:E39) -> 1958.2 | F41: =AVERAGE(F30:F39) -> 39.93203 | G41: =AVERAGE(G30:G39) -> 52.22 | H41: =(COUNTIF(H30:H39,"Yes")/10)*100 -> 0 | I41: =AVERAGE(I30:I39) -> 89.11 | J41: =AVERAGE(J30:J39) -> 56.037 | K41: =AVERAGE(K30:K39) -> 26.884 | L41: =AVERAGE(L30:L39) -> #DIV/0!
F42: =((D41-G41)/D41)*100 -> 40.103689

Sheet sp2_25_a5
A1: bins J (1° stage) | B1: 4 | C1: 16 | D1: 17 | E1: 18 | F1: 19 | G1: 20 | H1: 21 | I1: 22 | J1: 24 | K1: 26 | N1: # fixed bins | O1: OF | P1: Time | Q1: Gap | R1: LB
A2: deterministic solution | N2: 10 | O2: 98.97 | P2: 900 | Q2: 0.024957 | R2: 69.5
A3: EVP
O6: VSS%
O7: =((ABS(C25-D41))/D41)*100 -> 1.322303
A13: zEVP | B13: # bins extra | C13: OF | D13: time_execution | E13: Gap | F13: LB | G13: Optimality reached? | H13: O_fs | I13: F_fs | J13: F_ss | K13: #items
A14: 1 | B14: 0.68 | C14: 105.2 | D14: 4589 | E14: 2.4492 | F14: 10.26 | G14: =IF(E14=0,"Yes","No") -> No | H14: 94.08 | I14: 66.51 | J14: 22
A15: 2 | B15: 0.68 | C15: 105.04 | D15: 2484 | E15: 2.2891 | F15: 10.26 | G15: =IF(E15=0,"Yes","No") -> No | H15: 94.22 | I15: 66.17 | J15: 23.74
A16: 3 | B16: 1.04 | C16: 108.61 | D16: 1800 | E16: 1.3442 | F16: 107.15 | G16: =IF(E16=0,"Yes","No") -> No | H16: 91.12 | I16: 70.76 | J16: 40.31
A17: 4 | B17: 0.68 | C17: 104.79 | D17: 1800 | E17: 1.6 | F17: 103.12 | G17: =IF(E17=0,"Yes","No") -> No | H17: 94.44 | I17: 65.48 | J17: 18.73
A18: 5 | B18: 0.76 | C18: 106.08 | D18: 1388 | E18: 0.9549 | F18: 105.07 | G18: =IF(E18=0,"Yes","No") -> No | H18: 93.3 | I18: 66.9 | J18: 26.01
A19: 6 | B19: 0.68 | C19: 105.36 | D19: 2076 | E19: 5.2456 | F19: 99.84 | G19: =IF(E19=0,"Yes","No") -> No | H19: 93.93 | I19: 69.88 | J19: 26.79
A20: 7 | B20: 0.6 | C20: 104.4 | D20: 958 | E20: 0.9297 | F20: 103.43 | G20: =IF(E20=0,"Yes","No") -> No | H20: 94.79 | I20: 65.78 | J20: 27.98
A21: 8 | B21: 0.88 | C21: 107.42 | D21: 1800 | E21: 1.5786 | F21: 105.76 | G21: =IF(E21=0,"Yes","No") -> No | H21: 92.13 | I21: 67.79 | J21: 32.3
A22: 9 | B22: 1.16 | C22: 109.58 | D22: 1800 | E22: 3.8256 | F22: 105.39 | G22: =IF(E22=0,"Yes","No") -> No | H22: 90.32 | I22: 67.83 | J22: 30.56
A23: 10 | B23: 0.96 | C23: 107.85 | D23: 1739 | E23: 0.8871 | F23: 106.89 | G23: =IF(E23=0,"Yes","No") -> No | H23: 91.76 | I23: 70.03 | J23: 37.26
A25: avg | B25: =AVERAGE(B14:B23) -> 0.812 | C25: =AVERAGE(C14:C23) -> 106.433 | D25: =AVERAGE(D14:D23) -> 2043.4 | E25: =AVERAGE(E14:E23) -> 2.1104 | F25: =AVERAGE(F14:F23) -> 85.717 | G25: =(COUNTIF(G14:G23,"Yes")/10)*100 -> 0 | H25: =AVERAGE(H14:H23) -> 93.009 | I25: =AVERAGE(I14:I23) -> 67.713 | J25: =AVERAGE(J14:J23) -> 28.568 | K25: =AVERAGE(K14:K23) -> #DIV/0!
E26: =((C25-F25)/C25)*100 -> 19.463888
A29: Stochastic 2 stage | B29: # fixed bins | C29: bins extra | D29: OF | E29: time_execution | F29: Gap | G29: LB | H29: Optimality reached? | I29: O_fs | J29: F_fs | K29: F_ss | L29: # items
A30: 1 | B30: 8 | C30: 2.52 | D30: 86.27 | E30: 2745 | F30: 31.61 | G30: 59 | H30: =IF(F30=0,"Yes","No") -> No | I30: 75.39 | J30: 69.08 | K30: 58.28
A31: 2 | B31: 18 | C31: 2.6 | D31: 112.46 | E31: 4252 | F31: 46.6349 | G31: 60.01 | H31: =IF(F31=0,"Yes","No") -> No | I31: 85.15 | J31: 69.28 | K31: 34.5
A32: 3 | B32: 10 | C32: 1.52 | D32: 109.23 | E32: 5170 | F32: 42.9043 | G32: 62.37 | H32: =IF(F32=0,"Yes","No") -> No | I32: 88.44 | J32: 57.96 | K32: 54.37
A33: 4 | B33: 9 | C33: 3 | D33: 88.6 | E33: 3659 | F33: 41.0284 | G33: 52.25 | H33: =IF(F33=0,"Yes","No") -> No | I33: 76.38 | J33: 60.57 | K33: 59.74
A34: 5 | B34: 8 | C34: 3.12 | D34: 99.83 | E34: 3659 | F34: 47.401 | G34: 52.51 | H34: =IF(F34=0,"Yes","No") -> No | I34: 70.76 | J34: 56.4 | K34: 53.52
